Workbook
Name BALANCE: 'Sub Calc'!$G$52
Name consultant: 'Sub Labor'!$B$1
Name FIXFEE: 'Sub Calc'!$H$47
Name INVOICE: 'Sub Calc'!$H$51

Sheet Master File 
B3: Invoice No. | C3: TEST-mVRu-
B4: Invoice Date. | C4: 46198.5
B6: Period of Service: | C6: from | D6: 46143.5 | E6: to | G6: 46173.5
B10: Prime Cal 1-1
B11: Amount to data | C11: Previous | D11: hrs | E11: pre hrs
A12: Field | B12: ='Sub Calc'!J11 -> 133815.68 | C12: 122840 | D12: ='Sub Calc _revised'!F11 -> 1619 | E12: =1619-144 -> 1475
B13: ='Sub Calc'!J12 -> 147130.07 | C13: 133895.6
A14: Total | B14: ='Sub Calc'!J14 -> 280945.75 | C14: 235701.84
A15: SS OT Premium(Jordy) | B15: ='Sub Calc _revised'!J24 -> 1924 | C15: 1924
A16: SS DT Premium(Jordy) | B16: ='Sub Calc _revised'!J25 -> 1776 | C16: 1776
A17: Total | B17: =SUBTOTAL(9,B15:B16) -> 3700 | C17: 3700
A18: Fixed Fee | B18: ='Sub Calc'!J43 -> 22475.062 | C18: 20538.25
A20: FCCM Home (0.13% x Direct labor) | B20: ='Sub Calc'!J48 -> 0 | C20: 0
A21: FCCM Field (0.08% x Direct labor) | B21: ='Sub Calc'!J49 -> 0 | C21: 0
A22: Rounding
B26: 112776
B27: 122925.84
B28: 235701.84
B29: 1924
B30: 1776
B31: 3700
B32: 18856.148

Sheet Invoice
B1: Professional Service Agreement Invoice
L3: WSP Invoice No.
B4: Azad Engineering PC
B5: 1901 Harrison St. Suite 1100 | L5: Invoice Date
B6: Oakland, CA 94612 | L6: ='Master File '!C4 -> 46188
B7: Mahsa Azad | L7: Purchase Order No.
B8: (415) 606 -3802 | L8: 71994
B9: mahsa@azadeng.com | L9: Sub Invoice Number:
L10: ='Master File '!C3 -> A.04-02-12
L11: WSP Project No.: 30900569.7859
B12: Send To: | D12: WSP USA INC
D13: 3260 Lone Tree Way, Suite 104
D14: Antioch, CA 94509
D15: Email: candelaria.aldan@wsp.com
B19: Contact Person: | E19: Candelaria (Cindy) Aldan - Project Financial Analyst
B21: Agreement No: | E21: 6M8178 | L21: Project No:
B22: Work Plan Title: | E22: Assistant Resident Engineer / Inspector for Train Control and Communication Projects | L22: 47CJ016, 20LT008
B23: Services for the Period From: | L23: Terms:
B24: ='Master File '!D6 -> 46137 | G24: to | H24: ='Master File '!G6 -> 46171 | L24: Net 30
B25: Billed Line Items (against Purchase Order Line-Sch, Item/Description
B27: 1- 1 | C27: Work Plan A.04-02 | L27: 36254
D30: TOTAL AMOUNT DUE THIS INVOICE | L30: =SUM(L27:N29) -> 26189.777
B33: BILLING SUMMARY:
C34: Total Work Plan Budget | J34: 156185.34
C35: Total Billed This Period | J35: 36254
C36: Previously Billed Amount | J36: 50000
C37: Total Billed to Date Amount | J37: 86254
C38: Amount Remaining | J38: 69931.34
B42: I certify that the direct salaries invoiced herein for this period reflect those amounts actually paid to employees for the time period shown per corporate records.
M45: ='Master File '!C4 -> 46188
B46: Mahsa Azad, | D46: ,President | M46: Date

Sheet Sub Calc _revised
A1: =Invoice!B4 -> Azad Engineering PC | I1: Date: | J1: =Invoice!L6 -> 46188
A2: INVOICE DETAIL ATTACHMENT | I2: Invoice No. | J2: =Invoice!L10 -> A.04-02-12
I3: Work Plan No. | J3: =+Invoice!R2 -> 0
G4: Budget | H4: Amount This Period | I4: Previously Billed | J4: Amount To Date | K4: % Expended
D5: Hours to Date
A6: Labor | D6: Current | E6: Previous | F6: To Date
A7: Home & Branch (H&B) | D7: ='Sub Labor'!D18 -> 0 | E7: =+F7-D7 -> 0 | F7: =+'Sub Labor'!K18 -> 0 | H7: ='Sub Labor'!F18 -> 0 | I7: =+J7-H7 -> 0 | J7: =+N7 -> 0 | P7: Budget Increase:
A8: Fringe Benefits on Labor | G8: =G7*D8 -> 0 | H8: =ROUND(+$D8*H$7,2) -> 0 | I8: =+J8-H8 -> 0 | J8: =+N8 -> 0 | O8: 8 | P8: Target Total | Q8: 133202.19
A9: H&B Overhead Pool on Labor | G9: =G7*D9 -> 0 | H9: =ROUND(+$D9*H$7,2) -> 0 | I9: =+J9-H9 -> 0 | J9: =+N9 -> 0 | O9: 9 | P9: ODC | Q9: 4625
D10: =SUM(D8:D9) -> 0 | G10: =SUBTOTAL(9,G7:G9) -> 0 | H10: =SUBTOTAL(9,H7:H9) -> 0 | I10: =SUBTOTAL(9,I7:I9) -> 0 | J10: =SUBTOTAL(9,J7:J9) -> 0 | O10: 10 | P10: Fringe % | Q10: 1.09
A11: Field | D11: =+'Sub Labor'!D26 -> 144 | E11: ='Master File '!E12 -> 1475 | F11: =D11+E11 -> 1619 | G11: 68450 | H11: =+'Sub Labor'!F26 -> 10975.68 | I11: 66008 | J11: =H11+I11 -> 76983.68 | O11: 11 | P11: Fee % | Q11: 0.08
A12: Fringe Benefits | D12: 1.2058 | G12: 74610.51 | H12: ='Sub Labor'!I21 -> 13234.475 | I12: 71948.72 | J12: =H12+I12 -> 85183.195 | O12: 12 | P12: Field | Q12: =(Q8 - Q9) / ((1 + Q10) * (1 + Q11)) -> 56963.136
A13: Field Overhead Pool | H13: =ROUND(+$D13*H$11,2) -> 0 | I13: =+J13-H13 -> 0 | J13: =+N13 -> 0 | O13: 13 | P13: Fringe | Q13: =Q12*Q10 -> 62089.818
D14: =SUM(D12:D13) -> 1.2058 | G14: =SUBTOTAL(9,G11:G13) -> 143060.51 | H14: =SUBTOTAL(9,H11:H13) -> 24210.155 | I14: =SUBTOTAL(9,I11:I13) -> 137956.72 | J14: =SUBTOTAL(9,J11:J13) -> 162166.87 | O14: 14 | P14: Total Labor | Q14: =Q12+Q13 -> 119052.95
O15: 15 | P15: Fee | Q15: =Q14*Q11 -> 9524.2363
I16: 0 | J16: =+H16+I16 -> 0
I17: 0 | J17: =+H17+I17 -> 0
I18: 0 | J18: =+H18+I18 -> 0
G19: =SUBTOTAL(9,G16:G18) -> 0 | H19: =SUBTOTAL(9,H16:H18) -> 0 | I19: 0 | J19: =SUBTOTAL(9,J16:J18) -> 0
D20: Total Labor | G20: =SUBTOTAL(9,G7:G19) -> 143060.51 | H20: =SUBTOTAL(9,H7:H19) -> 24210.155 | I20: =SUBTOTAL(9,I7:I19) -> 137956.72 | J20: =SUBTOTAL(9,J7:J19) -> 162166.87 | K20: =J20/G20 -> 1.1335544 | P20: Grand Total (Check) | Q20: =Q14+Q15+Q9 -> 133202.19
A22: Other Direct Costs
G23: 1680 | H23: 0 | I23: =+J23-H23 -> 0 | J23: 0
D24: SS OT Premium(Jordy) | E24: 37/HR | F24: HRS | I24: 1924 | J24: =H24+I24 -> 1924
D25: SS DT Premium(Jordy) | E25: 74/HR | F25: HRS | I25: 1776 | J25: =H25+I25 -> 1776
H26: 0 | I26: =+J26-H26 -> 0 | J26: 0
B27: Car Rental | D27: 0 | E27: Days | F27: 0 | G27: =F27*D27 -> 0 | H27: 0 | I27: =+J27-H27 -> 0 | J27: 0
B28: Lodging | D28: 0 | E28: Nights | F28: 0 | G28: =F28*D28 -> 0 | H28: 0 | I28: =+J28-H28 -> 0 | J28: 0
B29: Meals | D29: 0 | E29: Each | F29: 0 | G29: =F29*D29 -> 0 | H29: 0 | I29: =+J29-H29 -> 0 | J29: 0
B30: Meals First/Last | D30: 0 | E30: Each | F30: 0 | G30: =F30*D30 -> 0 | H30: 0 | I30: =+J30-H30 -> 0 | J30: 0
D31: Total Other Direct Cost | G31: =SUBTOTAL(9,G22:G30) -> 1680 | H31: =SUBTOTAL(9,H22:H30) -> 0 | I31: =SUBTOTAL(9,I22:I30) -> 3700 | J31: =SUBTOTAL(9,J22:J30) -> 3700 | K31: =H31/G31 -> 0
A32: Subconsultants:
I33: 0 | J33: =SUM(H33:I33) -> 0
I34: 0 | J34: =SUM(H34:I34) -> 0
I35: 0 | J35: =SUM(H35:I35) -> 0
I36: 0 | J36: =SUM(H36:I36) -> 0
D37: Total Subconsultants | G37: =SUBTOTAL(9,G33:G36) -> 0 | H37: =SUBTOTAL(9,H33:H36) -> 0 | I37: =SUBTOTAL(9,I33:I36) -> 0 | J37: =SUBTOTAL(9,J33:J36) -> 0
A38: Project Management:
B39: PMAC | E39: 0 | G39: =(G20+G37)*E39 -> 0 | H39: =(H20+H37)*$E$39 -> 0 | I39: 0 | J39: =H39+I39 -> 0
D41: Total PMAC | G41: =SUBTOTAL(9,G39:G40) -> 0 | H41: =SUBTOTAL(9,H39:H40) -> 0 | I41: 0 | J41: =SUBTOTAL(9,J39:J40) -> 0 | K41: =J41/G41 -> #DIV/0!
A42: Fixed Fee
...

Sheet Progress Report
B1: BART ON-CALL CONSTRUCTION MANAGEMENT SERVICES
B2: Agreement No. 6M8178
B3: PROGRESS REPORT
B4: =I6 -> 46188
B6: =+Invoice!C27 -> Work Plan A.04-02 | D6: PO No.: | E6: =+Invoice!L8 -> 71994 | G6: Date: | I6: =+Invoice!L6 -> 46188
B7: =Invoice!E22 -> Assistant Resident Engineer / Inspector for Train Control and Communication Projects | F7: Period: | G7: ='Master File '!D6 -> 46137 | H7: to | I7: ='Master File '!G6 -> 46171
B9: Describe Work Performed/Accomplished During the Month (List Major Activities)
B10: Summarize Work Completed to Date (Milestones Completed and Dates) by Jordy Peralta
B11: • | C11: Performed daily inventory counts of TR4s, TVM Kits, CSC Transports, and Test TR4s
C12: stored at LMA to ensure installation readiness.
B13: • | C13: Updated Clipper TR4 equipment statuses in BART’s master tracking spreadsheet
C14: “CUBIC-BART_TR4_1599.”
B15: • | C15: Reviewed and audited technical reports submitted by technicians on faregates and
C16: vending machine upgrades.
B17: • | C17: Assisted with packaging and labeling of TR4 equipment returns with Cubic.
B18: •
B21: Concerns:
C22: N/A
B24: Recommendation of Corrective Action:
C25: N/A
B26: Percent of Work Completed (Physical): | E26: =+E30 -> 1.1453254
B28: Schedule: 24months. Time Passed: 11 months, Remaining 14 months. Comment: No change in schedule | K28: UPDATE
B29: Cost Forecast at Completion: Current approved budget is | F29: =+Invoice!J34 -> 156185.34 | G29: .
B30: Through this invoice, | D30: =Invoice!J37 -> 178883.04 | E30: =+D30/F29 -> 1.1453254 | F30: has been billed.
B32: If you have any questions, please contact the undersigned at (510) 282-4932
G35: =+I6 -> 46188
B36: Mahsa Azad, President | G36: Date

Sheet Sub Calc
A1: =Invoice!B4 -> Azad Engineering PC | I1: Date: | J1: =Invoice!L6 -> 46188
A2: INVOICE DETAIL ATTACHMENT | I2: Invoice No. | J2: =Invoice!L10 -> A.04-02-12
I3: Work Plan No. | J3: =+Invoice!R2 -> 0 | T3: REV
G4: Budget | H4: Amount This Period | I4: Previously Billed | J4: Amount To Date | K4: % Expended | N4: Total Billed
D5: Hours to Date
A6: Labor | D6: Current | E6: Previous | F6: To Date
A7: Home & Branch (H&B) | D7: ='Sub Labor'!D18 -> 0 | E7: =+F7-D7 -> 0 | F7: =+'Sub Labor'!K18 -> 0 | H7: ='Sub Labor'!F18 -> 0 | I7: =+J7-H7 -> 0 | J7: =+N7 -> 0 | N7: =SUM(O7:X7) -> 0
A8: Fringe Benefits on Labor | G8: =G7*D8 -> 0 | H8: =ROUND(+$D8*H$7,2) -> 0 | I8: =+J8-H8 -> 0 | J8: =+N8 -> 0
A9: H&B Overhead Pool on Labor | G9: =G7*D9 -> 0 | H9: =ROUND(+$D9*H$7,2) -> 0 | I9: =+J9-H9 -> 0 | J9: =+N9 -> 0
D10: =SUM(D8:D9) -> 0 | G10: =SUBTOTAL(9,G7:G9) -> 0 | H10: =SUBTOTAL(9,H7:H9) -> 0 | I10: =SUBTOTAL(9,I7:I9) -> 0 | J10: =SUBTOTAL(9,J7:J9) -> 0
A11: Field | D11: =+'Sub Labor'!D26 -> 144 | E11: ='Master File '!E12 -> 1475 | F11: =D11+E11 -> 1619 | G11: ='Sub Calc _revised'!G11 -> 68450 | H11: =+'Sub Labor'!F26 -> 10975.68 | I11: ='Master File '!C12 -> 122840 | J11: =H11+I11 -> 133815.68
A12: Fringe Benefits | D12: 1.09 | G12: =G11*D12 -> 74610.5 | H12: ='Sub Labor'!I21 -> 13234.475 | I12: ='Master File '!C13 -> 133895.6 | J12: =H12+I12 -> 147130.07
A13: Field Overhead Pool | H13: =ROUND(+$D13*H$11,2) -> 0 | I13: =+J13-H13 -> 0 | J13: =+N13 -> 0
D14: =SUM(D12:D13) -> 1.09 | G14: =SUBTOTAL(9,G11:G13) -> 143060.5 | H14: =SUBTOTAL(9,H11:H13) -> 24210.155 | I14: =SUBTOTAL(9,I11:I13) -> 256735.6 | J14: =SUBTOTAL(9,J11:J13) -> 280945.75
I16: 0 | J16: =+H16+I16 -> 0
I17: 0 | J17: =+H17+I17 -> 0
I18: 0 | J18: =+H18+I18 -> 0
G19: =SUBTOTAL(9,G16:G18) -> 0 | H19: =SUBTOTAL(9,H16:H18) -> 0 | I19: 0 | J19: =SUBTOTAL(9,J16:J18) -> 0
D20: Total Labor | G20: =SUBTOTAL(9,G7:G19) -> 143060.5 | H20: =SUBTOTAL(9,H7:H19) -> 24210.155 | I20: =SUBTOTAL(9,I7:I19) -> 256735.6 | J20: =SUBTOTAL(9,J7:J19) -> 280945.75 | K20: =J20/G20 -> 1.9638248
A22: Other Direct Costs
G23: 4625 | H23: 0 | I23: =+J23-H23 -> 0 | J23: 0
D24: SS OT Premium(Jordy) | E24: 37/HR | F24: 0/HRS | H24: 0 | I24: ='Master File '!C15 -> 1924 | J24: =H24+I24 -> 1924
D25: SS DT Premium(Jordy) | E25: 74/HR | F25: 0/HRS | I25: ='Master File '!C16 -> 1776 | J25: =H25+I25 -> 1776
H26: 0 | I26: =+J26-H26 -> 0 | J26: 0
B27: Car Rental | D27: 0 | E27: Days | F27: 0 | G27: =F27*D27 -> 0 | H27: 0 | I27: =+J27-H27 -> 0 | J27: 0
B28: Lodging | D28: 0 | E28: Nights | F28: 0 | G28: =F28*D28 -> 0 | H28: 0 | I28: =+J28-H28 -> 0 | J28: 0
B29: Meals | D29: 0 | E29: Each | F29: 0 | G29: =F29*D29 -> 0 | H29: 0 | I29: =+J29-H29 -> 0 | J29: 0
B30: Meals First/Last | D30: 0 | E30: Each | F30: 0 | G30: =F30*D30 -> 0 | H30: 0 | I30: =+J30-H30 -> 0 | J30: 0
D31: Total Other Direct Cost | G31: =SUBTOTAL(9,G22:G30) -> 4625 | H31: =SUBTOTAL(9,H22:H30) -> 0 | I31: =SUBTOTAL(9,I22:I30) -> 3700 | J31: =SUBTOTAL(9,J22:J30) -> 3700 | K31: =H31/G31 -> 0
A32: Subconsultants:
I33: 0 | J33: =SUM(H33:I33) -> 0
I34: 0 | J34: =SUM(H34:I34) -> 0
I35: 0 | J35: =SUM(H35:I35) -> 0
I36: 0 | J36: =SUM(H36:I36) -> 0
D37: Total Subconsultants | G37: =SUBTOTAL(9,G33:G36) -> 0 | H37: =SUBTOTAL(9,H33:H36) -> 0 | I37: =SUBTOTAL(9,I33:I36) -> 0 | J37: =SUBTOTAL(9,J33:J36) -> 0
A38: Project Management:
B39: PMAC | E39: 0 | G39: =(G20+G37)*E39 -> 0 | H39: =(H20+H37)*$E$39 -> 0 | I39: 0 | J39: =H39+I39 -> 0
D41: Total PMAC | G41: =SUBTOTAL(9,G39:G40) -> 0 | H41: =SUBTOTAL(9,H39:H40) -> 0 | I41: 0 | J41: =SUBTOTAL(9,J39:J40) -> 0 | K41: =J41/G41 -> #DIV/0!
A42: Fixed Fee
B43: Fixed Fee on Labor & Overhead | E43: 0.08 | G43: =G20*E43 -> 11444.84 | H43: ='Sub Labor'!I23 -> 1936.8124 | I43: ='Master File '!C18 -> 20538.25 | J43: =H43+I43 -> 22475.062
...

Sheet Sub Labor
B1: =Invoice!B4 -> Azad Engineering PC | D1: Invoice Date: | F1: =Invoice!L6 -> 46188 | I1: Max Rate Cap
B2: LABOR ATTACHMENT | D2: Invoice No.: | F2: =Invoice!L10 -> A.04-02-12 | I2: at $115
D3: Work Plan No.: | F3: ='Sub Calc'!J3 -> 0 | I3: Bill Rate Overide
I4: 44562 | K4: Total Billed Hours
A5: 1 | B5: Classification | C5: Name | D5: Hours | E5: Rate/Hour | F5: Amount | G5: Task No. | H5: Billed $ | K5: TOTAL HRS | U5: 45505
A6: 1 | B6: Home | H6: =+'Sub Calc'!D10+'Sub Calc'!E48 -> 0
A7: =IF(D7=0,"0","1") -> 0
A8: =IF(D8=0,"0","1") -> 0 | K8: =SUM(L8:U8) -> 0
A9: =IF(D9=0,"0","1") -> 0 | K9: =SUM(L9:U9) -> 0
A10: 1
A11: 1
A12: 1
A13: 1
A14: 1
A15: 1
A16: 1
A17: 1
A18: =IF(D18=0,"0","1") -> 0 | B18: SUBTOTAL (HOME) | D18: =SUBTOTAL(9,D7:D17) -> 0 | F18: =SUBTOTAL(9,F6:F17) -> 0 | H18: =SUM(H7:H17) -> 0
A19: 1 | B19: Field | H19: ='Sub Calc _revised'!D14 -> 1.2058
A20: =IF(D20=0,"0","1") -> 0 | B20: ARE | C20: John Smith | D20: 160 | E20: 95 | F20: 15200 | H20: 36210.41 | K20: =SUM(L20:U20) -> 0
A21: =IF(D21=0,"0","1") -> 1 | I21: =(D21+D23+D24)*E21*H19 -> 13234.475 | K21: =SUM(L21:U21) -> 0
I23: =(D21+D23+D24)*E21*(1+H19)*0.08 -> 1936.8124
A25: 1
A26: 1 | B26: SUBTOTAL (FIELD) | D26: =SUBTOTAL(9,D20:D25) -> 144 | F26: =SUBTOTAL(9,F20:F25) -> 10975.68 | H26: =SUM(H20:H25) -> 26146.967 | I26: =H26-I23 -> 24210.155
A27: 1
A28: 1
A29: 1 | B29: TOTAL LABOR | D29: =SUBTOTAL(9,D7:D28) -> 144 | F29: =SUBTOTAL(9,F7:F28) -> 10975.68 | H29: =H18+H26+0 -> 26146.967 | I29: Labor | M29: =SUM(M7:M28) -> 0 | N29: =SUM(N7:N28) -> 0 | O29: =SUM(O7:O28) -> 0 | P29: =SUM(P7:P28) -> 0 | Q29: =SUM(Q7:Q28) -> 0 | R29: =SUM(R8:R28) -> 0 | S29: =SUM(S8:S28) -> 0 | T29: =SUM(T8:T28) -> 0 | U29: =SUM(U8:U28) -> 0
A30: 1 | H30: =+'Sub Calc'!H31 -> 0 | I30: ODC
A31: 1 | H31: =SUM(H29:H30) -> 26146.967 | I31: manual

Sheet Prime ODCs
A1: Agreement No. 6M8149 Work Plan No. B.16-01
A2: Table of Other Direct Costs (ODCs)
A3: Month of | C3: =+Invoice!G23 -> 0
A6: No. | B6: Invoice Date | C6: Vendor Name | D6: Personnel Name | E6: Invoice Amount | F6: Purpose
A7: =Invoice!R$11 -> 0 | B7: 44538 | C7: WSP | D7: CONSOLACION, Mr. BENJAMIN L | F7: ER MILEAGE | G7: IE6881445
A8: =Invoice!R$11 -> 0 | B8: 44538 | C8: WSP | D8: CONSOLACION, Mr. BENJAMIN L | F8: ER AUTO - TOLLS/PARKING | G8: IE6881445
A9: =Invoice!R$11 -> 0 | B9: 44538 | C9: WSP | D9: CONSOLACION, Mr. BENJAMIN L | F9: ER AUTO - TOLLS/PARKING | G9: IE6881445
A10: =Invoice!R$11 -> 0 | B10: 44538 | C10: WSP | D10: CONSOLACION, Mr. BENJAMIN L | F10: ER AUTO - TOLLS/PARKING | G10: IE6881445
A11: =Invoice!R$11 -> 0 | B11: 44538 | C11: WSP | D11: CONSOLACION, Mr. BENJAMIN L | F11: ER MILEAGE | G11: IE6881445
A12: =Invoice!R$11 -> 0 | B12: 44546 | C12: WSP | D12: CONSOLACION, Mr. BENJAMIN L | F12: ER MILEAGE | G12: IE6881445
A13: =Invoice!R$11 -> 0 | B13: 44546 | C13: WSP | D13: CONSOLACION, Mr. BENJAMIN L | F13: ER AUTO - TOLLS/PARKING | G13: IE6881445
A14: =Invoice!R$11 -> 0 | B14: 44546 | C14: WSP | D14: CONSOLACION, Mr. BENJAMIN L | F14: ER TICKET FARE | G14: IE6881445
A15: =Invoice!R$11 -> 0 | B15: 44546 | C15: WSP | D15: CONSOLACION, Mr. BENJAMIN L | F15: ER MILEAGE | G15: IE6881445
A16: =Invoice!R$11 -> 0 | B16: 44496 | C16: WSP | D16: CONSOLACION, Mr. BENJAMIN L | E16: 0 | G16: IE6863524
A17: =Invoice!R$11 -> 0 | B17: 44496 | C17: WSP | D17: CONSOLACION, Mr. BENJAMIN L | E17: 0 | F17: ER MILEAGE | G17: IE6863524
A18: =Invoice!R$11 -> 0 | B18: 44496 | C18: WSP | D18: CONSOLACION, Mr. BENJAMIN L | E18: 0 | F18: ER AUTO - TOLLS/PARKING | G18: IE6863524
A19: =Invoice!R$11 -> 0 | B19: 44496 | C19: WSP | D19: CONSOLACION, Mr. BENJAMIN L | E19: 0 | F19: ER AUTO - TOLLS/PARKING | G19: IE6863524
D20: CONSOLACION, Mr. BENJAMIN L SUBTOTAL | E20: =SUBTOTAL(9,E7:E19) -> 0
A27: Grand Total | E27: =SUBTOTAL(9,E7:E19) -> 0 | I27: =+E27-H27 -> 0

Sheet ODC
A1: Table of Other Direct Costs (ODCs) | G1: Invoice Date: | H1: =Invoice!L6 -> 46188
G2: Invoice No.: | H2: =Invoice!L10 -> A.04-02-12
A3: Agreement No. | C3: =+Invoice!E21 -> 6M8178 | G3: Work Plan No. | H3: A.04-02
A6: No. | B6: Invoice Date | C6: Vendor Name | D6: Personnel Name | E6: Invoice Amount | F6: Purpose | J6: Inv #
A9: 1 | B9: 45835 | C9: AZAD | D9: Jordy | F9: SS OT Premium (Jordy)
A10: 1 | C10: AZAD | D10: Jordy | F10: SS OT Premium (Jordy)
A11: 2 | C11: AZAD | D11: Jordy | F11: SS DT Premium (Jordy)
A23: Grand Total | E23: =SUM(E7:E22) -> 0

Sheet MISC
A2: INVOICE ATTACHMENTS
B4: • | C4: Signed Progress Report
B5: • | C5: Receipts for all other direct costs and summary page
C6: • | D6: For travel related costs, please include:
C7: • | D7: Map printout for mileage and purpose of travel
C8: • | D8: GSA per diem page showing destination and rates
C9: • | D9: Detailed hotel receipts (not reservation)
B10: • | C10: Signed Pre-approvals (travel, overtime etc)
B11: • | C11: Timesheets (as required by PMs and for Term work plan type)

Sheet JP Week 1
A2: Weekly Timesheet
A3: Azad Engineering PC Timesheet
A5: Employee Name: | C5: Jordy Peralta | G5: Week Ending: | I5: =M6 -> 46143
G6: 46137 | H6: =G6+1 -> 46138 | I6: =H6+1 -> 46139 | J6: =I6+1 -> 46140 | K6: =J6+1 -> 46141 | L6: =K6+1 -> 46142 | M6: =L6+1 -> 46143
A7: Contract / Workplan | C7: Description | G7: Sat | H7: Sun | I7: Mon | J7: Tue | K7: Wed | L7: Thur | M7: Fri | N7: TOTAL
A9: 6M8178 A.04-01 | C9: Assistant Resident Engineer - Overtime | N9: =SUM(I9:M9) -> 0
A10: 6M8178 A.04-02 | C10: Assistant Resident Engineer - Straight Time-Night | M10: 0 | N10: =SUM(I10:M10) -> 0
A11: 6M8178 A.04-02 | C11: Assistant Resident Engineer - Overtime | N11: =SUM(I11:M11) -> 0
A12: 6M8178 A.04-02 | C12: Assistant Resident Engineer - Doubletime | N12: =H12+I12+J12+K12+L12+M12 -> 0
A13: PTO (Sick/Vacation) | M13: 8 | N13: =SUM(I13:M13) -> 8
A14: Holiday | N14: =SUM(I14:M14) -> 0
C16: TOTAL HOURS | G16: =SUM(G8:G15) -> 0 | H16: =SUM(H8:H15) -> 0 | I16: =SUM(I8:I15) -> 0 | J16: =SUM(J8:J15) -> 0 | K16: =SUM(K8:K15) -> 0 | L16: =SUM(L8:L15) -> 0 | M16: =SUM(M8:M15) -> 8 | N16: =SUM(G16:M16) -> 8
A18: Submitted by: | E18: Approved by:

Sheet JP Week 2
A2: Weekly Timesheet
A3: Azad Engineering PC Timesheet
A5: Employee Name: | C5: Jordy Peralta | G5: Week Ending: | I5: =M6 -> 46150
G6: ='JP Week 1'!M6+1 -> 46144 | H6: =G6+1 -> 46145 | I6: =H6+1 -> 46146 | J6: =I6+1 -> 46147 | K6: =J6+1 -> 46148 | L6: =K6+1 -> 46149 | M6: =L6+1 -> 46150
A7: Contract / Workplan | C7: Description | G7: Sat | H7: Sun | I7: Mon | J7: Tue | K7: Wed | L7: Thur | M7: Fri | N7: TOTAL
A9: 6M8178 A.04-02 | C9: Assistant Resident Engineer -Straight Time-Night | I9: 8 | J9: 8 | K9: 8 | L9: 8 | M9: 8 | N9: =SUM(I9:M9) -> 40
A10: 6M8178 A.04-02 | C10: Assistant Resident Engineer - Overtime | N10: =SUM(G10:M10) -> 0
A11: 6M8178 A.04-02 | C11: Assistant Resident Engineer - Doubletime | N11: =G11+H11+I11+J11+K11+L11 -> 0
A12: 6M8178 A.04-01 | C12: Assistant Resident Engineer - Doubletime | N12: =SUM(I12:M12) -> 0
A13: PTO (Sick/Vacation) | N13: =SUM(I13:M13) -> 0
A14: Holiday | C14: ` | N14: =SUM(I14:M14) -> 0
C16: TOTAL HOURS | G16: =SUM(G8:G15) -> 0 | H16: =SUM(H8:H15) -> 0 | I16: =SUM(I8:I15) -> 8 | J16: =SUM(J8:J15) -> 8 | K16: =SUM(K8:K15) -> 8 | L16: =SUM(L8:L15) -> 8 | M16: =SUM(M8:M15) -> 8 | N16: =SUM(G16:M16) -> 40
A18: Submitted by: | E18: Approved by:

Sheet JP Week 3
A2: Weekly Timesheet
A3: Azad Engineering PC Timesheet
A5: Employee Name: | C5: Jordy Peralta | G5: Week Ending: | I5: =M6 -> 46157
G6: ='JP Week 2'!M6+1 -> 46151 | H6: =G6+1 -> 46152 | I6: =H6+1 -> 46153 | J6: =I6+1 -> 46154 | K6: =J6+1 -> 46155 | L6: =K6+1 -> 46156 | M6: =L6+1 -> 46157
A7: Contract / Workplan | C7: Description | G7: Sat | H7: Sun | I7: Mon | J7: Tue | K7: Wed | L7: Thur | M7: Fri | N7: TOTAL
A9: 6M8178 A.04-02 | C9: Assistant Resident Engineer-Straight Time-Night | J9: 8 | K9: 8 | L9: 8 | M9: 8 | N9: =SUM(I9:M9) -> 32
A10: 6M8178 A.04-02 | C10: Assistant Resident Engineer - Overtime | N10: =SUM(G10:M10) -> 0
A11: 6M8178 A.04-02 | C11: Assistant Resident Engineer - Doubletime | N11: =SUM(G11:M11) -> 0
A12: PTO (Sick/Vacation) | I12: 8 | N12: =SUM(I12:M12) -> 8
A13: Holiday | N13: =SUM(I13:M13) -> 0
C15: TOTAL HOURS | G15: =SUM(G8:G14) -> 0 | H15: =SUM(H8:H14) -> 0 | I15: =SUM(I8:I14) -> 8 | J15: =SUM(J8:J14) -> 8 | K15: =SUM(K8:K14) -> 8 | L15: =SUM(L8:L14) -> 8 | M15: =SUM(M8:M14) -> 8 | N15: =SUM(G15:M15) -> 40
A17: Submitted by: | E17: Approved by:

Sheet JP Week 4
A2: Weekly Timesheet
A3: Azad Engineering PC Timesheet
A5: Employee Name: | C5: Jordy Peralta | G5: Week Ending: | I5: =M6 -> 46164
G6: ='JP Week 3'!M6+1 -> 46158 | H6: =G6+1 -> 46159 | I6: =H6+1 -> 46160 | J6: =I6+1 -> 46161 | K6: =J6+1 -> 46162 | L6: =K6+1 -> 46163 | M6: =L6+1 -> 46164
A7: Contract / Workplan | C7: Description | G7: Sat | H7: Sun | I7: Mon | J7: Tue | K7: Wed | L7: Thur | M7: Fri | N7: TOTAL
A9: 6M8178 A.04-02 | C9: Assistant Resident Engineer-Straight Time-Night | I9: 8 | J9: 8 | K9: 8 | L9: 8 | M9: 8 | N9: =SUM(I9:M9) -> 40
A10: 6M8178 A.04-02 | C10: Assistant Resident Engineer - Overtime | N10: =G10+H10+I10+J10+K10+L10+M10 -> 0
A11: 6M8178 A.04-02 | C11: Assistant Resident Engineer - Doubletime | N11: =SUM(G11:M11) -> 0
A12: PTO (Sick/Vacation) | N12: =SUM(I12:M12) -> 0
A13: Holiday | N13: =SUM(I13:M13) -> 0
C15: TOTAL HOURS | G15: =SUM(G8:G14) -> 0 | H15: =SUM(H8:H14) -> 0 | I15: =SUM(I8:I14) -> 8 | J15: =SUM(J8:J14) -> 8 | K15: =SUM(K8:K14) -> 8 | L15: =SUM(L8:L14) -> 8 | M15: =SUM(M8:M14) -> 8 | N15: =SUM(G15:M15) -> 40
A17: Submitted by: | E17: Approved by:

Sheet JP Week6
A2: Weekly Timesheet
A3: Azad Engineering PC Timesheet
A5: Employee Name: | C5: Jordy Peralta | G5: Week Ending: | I5: =M6 -> 45842
G6: 45836 | H6: =G6+1 -> 45837 | I6: =H6+1 -> 45838 | J6: =I6+1 -> 45839 | K6: =J6+1 -> 45840 | L6: =K6+1 -> 45841 | M6: =L6+1 -> 45842
A7: Contract / Workplan | C7: Description | G7: Sat | H7: Sun | I7: Mon | J7: Tue | K7: Wed | L7: Thur | M7: Fri | N7: TOTAL
A9: 6M8178 A.05-01 | C9: Assistant Resident Engineer-Straight Time | N9: =SUM(I9:M9) -> 0
A10: 6M8178 A.04-01 | C10: Assistant Resident Engineer - Overtime | N10: 12
A11: 6M8178 A.04-01 | C11: Assistant Resident Engineer - Doubletime | N11: =SUM(I11:M11) -> 0
A12: PTO (Sick/Vacation) | N12: =SUM(I12:M12) -> 0
A13: Holiday | I13: 8 | N13: =SUM(I13:M13) -> 8
C15: TOTAL HOURS | G15: =SUM(G8:G14) -> 0 | H15: =SUM(H8:H14) -> 0 | I15: =SUM(I8:I14) -> 8 | J15: =SUM(J8:J14) -> 0 | K15: =SUM(K8:K14) -> 0 | L15: =SUM(L8:L14) -> 0 | M15: =SUM(M8:M14) -> 0 | N15: 52
A17: Submitted by: | E17: Approved by:

Sheet JP Week 5
A2: Weekly Timesheet
A3: Azad Engineering PC Timesheet
A5: Employee Name: | C5: Jordy Peralta | G5: Week Ending: | I5: =M6 -> 46171
G6: ='JP Week 4'!M6+1 -> 46165 | H6: =G6+1 -> 46166 | I6: =H6+1 -> 46167 | J6: =I6+1 -> 46168 | K6: =J6+1 -> 46169 | L6: =K6+1 -> 46170 | M6: =L6+1 -> 46171
A7: Contract / Workplan | C7: Description | G7: Sat | H7: Sun | I7: Mon | J7: Tue | K7: Wed | L7: Thur | M7: Fri | N7: TOTAL
A9: 6M8178 A.04-02 | C9: Assistant Resident Engineer | J9: 8 | K9: 8 | L9: 8 | M9: 8 | N9: =SUM(I9:M9) -> 32
A10: 6M8178 A.04-02 | C10: Assistant Resident Engineer-Night | N10: =G10+H10+I10+J10+K10+L10+M10 -> 0
A11: 6M8178 A.04-02 | C11: Assistant Resident Engineer - Overtime | N11: =SUM(G11:M11) -> 0
A12: 6M8178 A.04-02 | C12: Assistant Resident Engineer - Doubletime | N12: =SUM(I12:M12) -> 0
A13: PTO (Sick/Vacation) | N13: =SUM(I13:M13) -> 0
A14: Holiday | I14: 8 | N14: =SUM(I14:M14) -> 8
C16: TOTAL HOURS | G16: =SUM(G8:G15) -> 0 | H16: =SUM(H8:H15) -> 0 | I16: =SUM(I8:I15) -> 8 | J16: =SUM(J8:J15) -> 8 | K16: =SUM(K8:K15) -> 8 | L16: =SUM(L8:L15) -> 8 | M16: =SUM(M8:M15) -> 8 | N16: =SUM(G16:M16) -> 40
A19: Submitted by: | E19: Approved by:
